<?xml version="1.0" encoding="UTF-8"?>
<testsuite name="test1"
           tests="3"
           failures="2"
           errors="0"
           skipped="0"
           time="0.052">
  <properties />
            <testcase name="f2" time="0.004" classname="com.UItest.NewTest">
                <failure type="java.lang.AssertionError"
                  message="expected [5] but found [4]"
              >
<![CDATA[java.lang.AssertionError: expected [5] but found [4]
  org.testng.Assert.fail(Assert.java:94)
  org.testng.Assert.failNotEquals(Assert.java:513)
  org.testng.Assert.assertEqualsImpl(Assert.java:135)
  org.testng.Assert.assertEquals(Assert.java:116)
  org.testng.Assert.assertEquals(Assert.java:389)
  org.testng.Assert.assertEquals(Assert.java:399)
  com.UItest.NewTest.f2(NewTest.java:22)
  sun.reflect.NativeMethodAccessorImpl.invoke0(Native Method)
  sun.reflect.NativeMethodAccessorImpl.invoke(Unknown Source)
  sun.reflect.DelegatingMethodAccessorImpl.invoke(Unknown Source)
  java.lang.reflect.Method.invoke(Unknown Source)
  org.testng.internal.MethodInvocationHelper.invokeMethod(MethodInvocationHelper.java:104)
  org.testng.internal.Invoker.invokeMethod(Invoker.java:645)
  org.testng.internal.Invoker.invokeTestMethod(Invoker.java:851)
  org.testng.internal.Invoker.invokeTestMethods(Invoker.java:1177)
  org.testng.internal.TestMethodWorker.invokeTestMethods(TestMethodWorker.java:129)
  org.testng.internal.TestMethodWorker.run(TestMethodWorker.java:112)
  org.testng.TestRunner.privateRun(TestRunner.java:756)
  org.testng.TestRunner.run(TestRunner.java:610)
  org.testng.SuiteRunner.runTest(SuiteRunner.java:387)
  org.testng.SuiteRunner.runSequentially(SuiteRunner.java:382)
  org.testng.SuiteRunner.privateRun(SuiteRunner.java:340)
  org.testng.SuiteRunner.run(SuiteRunner.java:289)
  org.testng.SuiteRunnerWorker.runSuite(SuiteRunnerWorker.java:52)
  org.testng.SuiteRunnerWorker.run(SuiteRunnerWorker.java:86)
  org.testng.TestNG.runSuitesSequentially(TestNG.java:1293)
  org.testng.TestNG.runSuitesLocally(TestNG.java:1218)
  org.testng.TestNG.runSuites(TestNG.java:1133)
  org.testng.TestNG.run(TestNG.java:1104)
  org.testng.remote.AbstractRemoteTestNG.run(AbstractRemoteTestNG.java:114)
  org.testng.remote.RemoteTestNG.initAndRun(RemoteTestNG.java:251)
  org.testng.remote.RemoteTestNG.main(RemoteTestNG.java:77)
]]>
      </failure>

          </testcase>
            <testcase name="f" time="0.044" classname="com.UItest.NewTest">
                <failure type="java.lang.AssertionError"
                  message="expected [3] but found [2]"
              >
<![CDATA[java.lang.AssertionError: expected [3] but found [2]
  org.testng.Assert.fail(Assert.java:94)
  org.testng.Assert.failNotEquals(Assert.java:513)
  org.testng.Assert.assertEqualsImpl(Assert.java:135)
  org.testng.Assert.assertEquals(Assert.java:116)
  org.testng.Assert.assertEquals(Assert.java:389)
  org.testng.Assert.assertEquals(Assert.java:399)
  com.UItest.NewTest.f(NewTest.java:11)
  sun.reflect.NativeMethodAccessorImpl.invoke0(Native Method)
  sun.reflect.NativeMethodAccessorImpl.invoke(Unknown Source)
  sun.reflect.DelegatingMethodAccessorImpl.invoke(Unknown Source)
  java.lang.reflect.Method.invoke(Unknown Source)
  org.testng.internal.MethodInvocationHelper.invokeMethod(MethodInvocationHelper.java:104)
  org.testng.internal.Invoker.invokeMethod(Invoker.java:645)
  org.testng.internal.Invoker.invokeTestMethod(Invoker.java:851)
  org.testng.internal.Invoker.invokeTestMethods(Invoker.java:1177)
  org.testng.internal.TestMethodWorker.invokeTestMethods(TestMethodWorker.java:129)
  org.testng.internal.TestMethodWorker.run(TestMethodWorker.java:112)
  org.testng.TestRunner.privateRun(TestRunner.java:756)
  org.testng.TestRunner.run(TestRunner.java:610)
  org.testng.SuiteRunner.runTest(SuiteRunner.java:387)
  org.testng.SuiteRunner.runSequentially(SuiteRunner.java:382)
  org.testng.SuiteRunner.privateRun(SuiteRunner.java:340)
  org.testng.SuiteRunner.run(SuiteRunner.java:289)
  org.testng.SuiteRunnerWorker.runSuite(SuiteRunnerWorker.java:52)
  org.testng.SuiteRunnerWorker.run(SuiteRunnerWorker.java:86)
  org.testng.TestNG.runSuitesSequentially(TestNG.java:1293)
  org.testng.TestNG.runSuitesLocally(TestNG.java:1218)
  org.testng.TestNG.runSuites(TestNG.java:1133)
  org.testng.TestNG.run(TestNG.java:1104)
  org.testng.remote.AbstractRemoteTestNG.run(AbstractRemoteTestNG.java:114)
  org.testng.remote.RemoteTestNG.initAndRun(RemoteTestNG.java:251)
  org.testng.remote.RemoteTestNG.main(RemoteTestNG.java:77)
]]>
      </failure>

          </testcase>
  
  
            <testcase name="f1" time="0.004" classname="com.UItest.NewTest" />
      
</testsuite>
